Workbook

Sheet Day1_Overview
B2: Day 1 – Dataset Selection & Import
B3: Dataset: Perfume_Data.xlsx (eBay perfume listings — Men's & Women's)
B5: Key Observations
B6: 1. Structure: two sheets of equal size — "Mens perfume" and "Womens perfume" — each with 1,000 listings and 9 columns (Brand, Type, Price, Price with Currency, Available, Available Text, Sold, Last Updated, Item Location).
B8: 2. Data types: PRICE, Available, and sold are numeric; the remaining columns (Brand, TYPE, priceWithCurrency, availableText, last Updated, Item Location) are text. "last Updated" is stored as text rather than a true date/time.
B10: 3. Missing values: gaps exist in Available (~111 Mens / 131 Womens rows), sold (6 / 16 rows), last Updated (53 / 73 rows), and a handful in Brand and TYPE — Available and last Updated are the most incomplete columns.
B12: 4. Data quality issues: brand names aren't standardized (e.g. "Dolce&Gabbana" vs "Dolce & Gabbana", "As Show" vs "AS SHOWN"); Item Location mixes city/state/country inconsistently; availableText bundles two facts (stock + sold) into one string; the Womens sheet has 3 exact duplicate rows.
B15: Data Profile (live formulas — updates automatically if data changes)
B17: Column | C17: Sheet | D17: Data Type | E17: Missing Count | F17: Missing %
B18: Brand | C18: Mens perfume | D18: Text | E18: =COUNTBLANK('Mens perfume'!A2:A1001) -> 1 | F18: =E18/1000 -> 0.001
B19: TYPE | C19: Mens perfume | D19: Text | E19: =COUNTBLANK('Mens perfume'!B2:B1001) -> 2 | F19: =E19/1000 -> 0.002
B20: PRICE | C20: Mens perfume | D20: Numeric | E20: =COUNTBLANK('Mens perfume'!C2:C1001) -> 0 | F20: =E20/1000 -> 0
B21: priceWithCurrency | C21: Mens perfume | D21: Text | E21: =COUNTBLANK('Mens perfume'!D2:D1001) -> 0 | F21: =E21/1000 -> 0
B22: Available | C22: Mens perfume | D22: Numeric | E22: =COUNTBLANK('Mens perfume'!E2:E1001) -> 111 | F22: =E22/1000 -> 0.111
B23: availableText | C23: Mens perfume | D23: Text | E23: =COUNTBLANK('Mens perfume'!F2:F1001) -> 3 | F23: =E23/1000 -> 0.003
B24: sold | C24: Mens perfume | D24: Numeric | E24: =COUNTBLANK('Mens perfume'!G2:G1001) -> 6 | F24: =E24/1000 -> 0.006
B25: last Updated | C25: Mens perfume | D25: Text (date-like) | E25: =COUNTBLANK('Mens perfume'!H2:H1001) -> 53 | F25: =E25/1000 -> 0.053
B26: Item Location | C26: Mens perfume | D26: Text | E26: =COUNTBLANK('Mens perfume'!I2:I1001) -> 0 | F26: =E26/1000 -> 0
B27: brand | C27: Womens perfume | D27: Text | E27: =COUNTBLANK('Womens perfume'!A2:A1001) -> 1 | F27: =E27/1000 -> 0.001
B28: type | C28: Womens perfume | D28: Text | E28: =COUNTBLANK('Womens perfume'!B2:B1001) -> 2 | F28: =E28/1000 -> 0.002
B29: price | C29: Womens perfume | D29: Numeric | E29: =COUNTBLANK('Womens perfume'!C2:C1001) -> 0 | F29: =E29/1000 -> 0
B30: priceWithCurrency | C30: Womens perfume | D30: Text | E30: =COUNTBLANK('Womens perfume'!D2:D1001) -> 0 | F30: =E30/1000 -> 0
B31: available | C31: Womens perfume | D31: Numeric | E31: =COUNTBLANK('Womens perfume'!E2:E1001) -> 131 | F31: =E31/1000 -> 0.131
B32: availableText | C32: Womens perfume | D32: Text | E32: =COUNTBLANK('Womens perfume'!F2:F1001) -> 8 | F32: =E32/1000 -> 0.008
B33: sold | C33: Womens perfume | D33: Numeric | E33: =COUNTBLANK('Womens perfume'!G2:G1001) -> 16 | F33: =E33/1000 -> 0.016
B34: lastUpdated | C34: Womens perfume | D34: Text (date-like) | E34: =COUNTBLANK('Womens perfume'!H2:H1001) -> 73 | F34: =E34/1000 -> 0.073
B35: itemLocation | C35: Womens perfume | D35: Text | E35: =COUNTBLANK('Womens perfume'!I2:I1001) -> 0 | F35: =E35/1000 -> 0
B37: Summary Stats
B38: Total rows – Mens perfume | C38: =COUNTA('Mens perfume'!A2:A1001) -> 999
B39: Total rows – Womens perfume | C39: =COUNTA('Womens perfume'!A2:A1001) -> 999
B40: Duplicate rows – Mens perfume | C40: 0
B41: Duplicate rows – Womens perfume | C41: 3

Sheet Mens perfume
A1: Brand | B1: TYPE | C1: PRICE | D1: priceWithCurrency | E1: Available | F1: availableText | G1: sold | H1: last Updated | I1: Item Location
A2: Dior | B2: Eau de Parfum | C2: 84.99 | D2: US $84.99/ea | E2: 10 | F2: More than 10 available / 116 sold | G2: 116 | H2: May 24, 2024 10:03:04 PDT | I2: Allen Park, Michigan, United States
A3: AS SHOW | B3: Eau de Parfum | C3: 109.99 | D3: US $109.99 | E3: 8 | F3: 8 available / 48 sold | G3: 48 | H3: May 23, 2024 23:07:49 PDT | I3: Atlanta, Georgia, Canada
A4: Unbranded | B4: Eau de Toilette | C4: 100 | D4: US $100.00 | E4: 10 | F4: More than 10 available / 27 sold | G4: 27 | H4: May 22, 2024 21:55:43 PDT | I4: Dearborn, Michigan, United States
A5: Giorgio Armani | B5: Eau de Toilette | C5: 44.99 | D5: US $44.99/ea | E5: 2 | F5: 2 available / 159 sold | G5: 159 | H5: May 24, 2024 03:30:43 PDT | I5: Reinholds, Pennsylvania, United States
A6: Lattafa | B6: Fragrances | C6: 16.91 | D6: US $16.91 | F6: Limited quantity available / 156 sold | G6: 156 | H6: May 24, 2024 07:56:25 PDT | I6: Brooklyn, New York, United States
A7: Multiple Brands | B7: Perfume | C7: 14.99 | D7: US $14.99 | E7: 10 | F7: More than 10 available / 79 sold | G7: 79 | H7: May 23, 2024 06:57:41 PDT | I7: Houston, Texas, United States
A8: Maison Alhambra | B8: Eau de Parfum | C8: 30.99 | D8: US $30.99/ea | E8: 9 | F8: 9 available / 39 sold | G8: 39 | H8: May 16, 2024 13:42:49 PDT | I8: Englewood Cliffs, New Jersey, United States
A9: Unbranded | B9: Eau de Parfum | C9: 85 | D9: US $85.00 | F9: Last One / 6 sold | G9: 6 | H9: May 24, 2024 00:10:39 PDT | I9: Ithaca, New York, United States
A10: Unbranded | B10: / | C10: 15.89 | D10: US $15.89 | E10: 10 | F10: 10 available / 17 sold | G10: 17 | H10: May 24, 2024 09:08:14 PDT | I10: shanghai, China
A11: Gucci | B11: Eau de Parfum | C11: 49.99 | D11: US $49.99/ea | E11: 8 | F11: 8 available / 68 sold | G11: 68 | H11: May 23, 2024 07:21:23 PDT | I11: Dearborn Heights, Michigan, United States
A12: Ralph Lauren | B12: Eau de Toilette | C12: 34.99 | D12: US $34.99/ea | E12: 10 | F12: More than 10 available / 615 sold | G12: 615 | H12: May 24, 2024 07:53:23 PDT | I12: Ecorse, Michigan, United States
A13: Dolce&Gabbana | B13: Eau de Toilette | C13: 29.95 | D13: US $29.95/ea | E13: 7 | F13: 7 available / 458 sold | G13: 458 | H13: May 23, 2024 08:37:49 PDT | I13: Warren, Michigan, United States
A14: SECERTMU | B14: Perfume | C14: 15.99 | D14: US $15.99 | E14: 10 | F14: More than 10 available / 889 sold | G14: 889 | H14: May 21, 2024 19:20:12 PDT | I14: San Francisco, California, United States
A15: As Show | B15: Eau de Parfum | C15: 59.99 | D15: US $59.99/ea | E15: 9 | F15: 9 available / 63 sold | G15: 63 | H15: May 23, 2024 03:08:18 PDT | I15: Dayton,New Jersey, Hong Kong
A16: Versace | B16: Eau de Toilette | C16: 34.99 | D16: US $34.99/ea | E16: 7 | F16: 7 available / 136 sold | G16: 136 | H16: May 24, 2024 00:02:27 PDT | I16: Warren, Michigan, United States
A17: Paco Rabanne | B17: PARFUM | C17: 68.99 | D17: US $68.99/ea | E17: 2 | F17: 2 available / 20 sold | G17: 20 | H17: May 24, 2024 02:41:49 PDT | I17: San Jose, California, United States
A18: Grandeur | B18: Eau de Parfum | C18: 37.99 | D18: US $37.99 | E18: 10 | F18: More than 10 available / 44 sold | G18: 44 | H18: May 24, 2024 08:14:43 PDT | I18: Miami, Florida, United States
A19: Armaf | B19: Eau de Toilette | C19: 29.99 | D19: US $29.99/ea | E19: 5 | F19: 5 available / 384 sold | G19: 384 | H19: May 24, 2024 05:13:20 PDT | I19: Hamtramck, Michigan, United States
A20: Carolina Herrera | B20: Eau de Toilette | C20: 39.99 | D20: US $39.99/ea | E20: 10 | F20: More than 10 available / 236 sold | G20: 236 | H20: May 23, 2024 08:48:22 PDT | I20: Flat Lick, Kentucky, United States
A21: Dior | B21: Eau de Toilette | C21: 83.95 | D21: US $83.95 | E21: 4 | F21: 4 available / 22 sold | G21: 22 | H21: May 22, 2024 14:31:55 PDT | I21: Elmhurst, New York, United States
A22: Dolce & Gabbana | B22: Eau de Toilette | C22: 29.94 | D22: US $29.94/ea | F22: Limited quantity available / 9,208 sold | G22: 9208 | H22: May 23, 2024 20:04:11 PDT | I22: Hackensack, New Jersey, United States
A23: Clinique | B23: Eau de Toilette | C23: 21.99 | D23: US $21.99/ea | E23: 4 | F23: 4 available / 86 sold | G23: 86 | H23: May 21, 2024 14:28:23 PDT | I23: Miami, Florida, United States
A24: Dumont | B24: Fragrances | C24: 49.99 | D24: US $49.99 | E24: 3 | F24: 3 available / 187 sold | G24: 187 | H24: May 24, 2024 09:02:39 PDT | I24: Brooklyn, New York, United States
A25: Afnan | B25: Eau de Parfum | C25: 33.7 | D25: US $33.70 | E25: 10 | F25: More than 10 available / 131 sold | G25: 131 | H25: May 21, 2024 14:00:54 PDT | I25: Dallas, Texas, United States
A26: Versace | B26: Eau de Toilette | C26: 35.99 | D26: US $35.99 | E26: 2 | F26: 2 available / 43 sold | G26: 43 | H26: May 24, 2024 00:13:55 PDT | I26: Pomona, California, United States
A27: Azzaro | B27: Parfum | C27: 89.97 | D27: US $89.97/ea | E27: 10 | F27: 10 available / 920 sold | G27: 920 | H27: May 24, 2024 08:32:16 PDT | I27: Katy, Texas, United States
A28: Unbranded | B28: Eau de Parfum | C28: 92.99 | D28: US $92.99 | E28: 5 | F28: 5 available / 19 sold | G28: 19 | H28: May 24, 2024 00:01:17 PDT | I28: College Point, New York, United States
A29: Azzaro | B29: Eau de Parfum | C29: 87.99 | D29: US $87.99 | E29: 2 | F29: 2 available / 4 sold | G29: 4 | I29: NEW YORK, United States
A30: Giorgio Armani | B30: Eau de Parfum | C30: 119.99 | D30: US $119.99 | E30: 10 | F30: 10 available / 34 sold | G30: 34 | H30: May 24, 2024 07:16:53 PDT | I30: New York,USA, Hong Kong
A31: Penhaligon's | B31: Eau de Parfum | C31: 99.99 | D31: US $99.99 | F31: Last One / 30 sold | G31: 30 | H31: May 20, 2024 04:16:27 PDT | I31: Brenham, Texas, United States
A32: Bharara | B32: Eau de Parfum | C32: 51.91 | D32: US $51.91/ea | E32: 4 | F32: 4 available / 47 sold | G32: 47 | H32: May 19, 2024 13:15:33 PDT | I32: Richmond Hill, New York, United States
A33: Paco Rabanne | B33: Eau de Toilette | C33: 49.99 | D33: US $49.99/ea | E33: 8 | F33: 8 available / 170 sold | G33: 170 | H33: May 23, 2024 07:03:35 PDT | I33: Dexter, Michigan, United States
A34: Armaf | B34: Eau de Toilette | C34: 32.85 | D34: US $32.85/ea | E34: 10 | F34: More than 10 available / 8,385 sold | G34: 8385 | H34: May 17, 2024 15:41:45 PDT | I34: Houston, Texas, United States
A35: Valentino | B35: Eau de Toilette | C35: 89.97 | D35: US $89.97/ea | E35: 10 | F35: 10 available / 295 sold | G35: 295 | H35: May 24, 2024 08:44:55 PDT | I35: Katy, Texas, United States
A36: Guy Laroche | B36: Eau de Toilette | C36: 16.98 | D36: US $16.98/ea | E36: 620 | F36: 620 available / 2,345 sold | G36: 2345 | H36: May 23, 2024 18:45:23 PDT | I36: Dallas, Texas, United States
A37: Montblanc | B37: Eau de Toilette | C37: 32.89 | D37: US $32.89/ea | E37: 383 | F37: 383 available / 5,032 sold | G37: 5032 | H37: May 21, 2024 07:59:07 PDT | I37: Dallas, Texas, United States
A38: Rasasi | B38: Eau de Parfum | C38: 45.11 | D38: US $45.11 | F38: Limited quantity available / 258 sold | G38: 258 | H38: May 24, 2024 09:50:28 PDT | I38: Brooklyn, New York, United States
A39: Maison Alhambra | B39: Fragrances | C39: 19.73 | D39: US $19.73 | F39: Limited quantity available / 55 sold | G39: 55 | H39: May 24, 2024 07:02:34 PDT | I39: Brooklyn, New York, United States
A40: Armaf | B40: Eau de Parfum | C40: 39.99 | D40: US $39.99/ea | E40: 8 | F40: 8 available / 276 sold | G40: 276 | H40: May 24, 2024 06:26:11 PDT | I40: Phoenix, Arizona, United States
...

Sheet Womens perfume
A1: brand | B1: type | C1: price | D1: priceWithCurrency | E1: available | F1: availableText | G1: sold | H1: lastUpdated | I1: itemLocation
A2: Carolina Herrera | B2: Eau de Parfum | C2: 43.99 | D2: US $43.99/ea | E2: 2 | F2: 2 available / 393 sold | G2: 393 | H2: May 23, 2024 10:43:50 PDT | I2: Thomasville, Alabama, United States
A3: As Shown | B3: Eau de Parfum | C3: 79.99 | D3: US $79.99 | E3: 5 | F3: 5 available / 40 sold | G3: 40 | H3: May 24, 2024 00:15:48 PDT | I3: New Jersey, Hong Kong
A4: PRADA | B4: Eau de Parfum | C4: 59.99 | D4: US $59.99 | E4: 10 | F4: More than 10 available / 35 sold | G4: 35 | H4: May 14, 2024 20:54:25 PDT | I4: Orange, New Jersey, United States
A5: As Show | B5: Eau de Parfum | C5: 59.99 | D5: US $59.99/ea | E5: 10 | F5: More than 10 available / 9 sold | G5: 9 | H5: May 23, 2024 01:23:05 PDT | I5: USA, New Jersey, Hong Kong
A6: Khadlaj | B6: Eau de Parfum | C6: 29.99 | D6: US $29.99/ea | E6: 10 | F6: More than 10 available | I6: Little Ferry, New Jersey, United States
A7: Viktor & Rolf | B7: Eau de Parfum | C7: 51.99 | D7: US $51.99/ea | E7: 8 | F7: 8 available / 184 sold | G7: 184 | H7: May 23, 2024 10:44:09 PDT | I7: Warren, Michigan, United States
A8: AS SHOW | B8: Eau de Parfum | C8: 58.99 | D8: US $58.99 | F8: Out of Stock / 18 sold | G8: 18 | H8: May 24, 2024 00:15:13 PDT | I8: Astoria, New York, United States
A9: Versace | B9: Eau de Toilette | C9: 52.79 | D9: US $52.79/ea | E9: 6 | F9: 6 available / 258 sold | G9: 258 | H9: May 21, 2024 06:41:13 PDT | I9: Dexter, Michigan, United States
A10: Versace | B10: Eau de Toilette | C10: 29.99 | D10: US $29.99 | F10: Last One / 251 sold | G10: 251 | H10: May 23, 2024 22:39:02 PDT | I10: Jamaica, New York, United States
A11: Lattafa | B11: Eau de Parfum | C11: 22.75 | D11: US $22.75/ea | E11: 10 | F11: More than 10 available / 174 sold | G11: 174 | H11: May 24, 2024 00:25:04 PDT | I11: New York, New York, United States
A12: Yves Saint Laurent | B12: Eau de Parfum | C12: 39.99 | D12: US $39.99/ea | E12: 10 | F12: More than 10 available / 77 sold | G12: 77 | H12: May 24, 2024 11:01:13 PDT | I12: Ecorse, Michigan, United States
A13: Gucci | B13: Eau de Parfum | C13: 64.99 | D13: US $64.99/ea | E13: 10 | F13: More than 10 available / 35 sold | G13: 35 | H13: May 24, 2024 11:01:04 PDT | I13: Ecorse, Michigan, United States
A14: Carolina Herrera | B14: Eau de Parfum | C14: 60.99 | D14: US $60.99/ea | E14: 2 | F14: 2 available / 51 sold | G14: 51 | H14: May 23, 2024 16:56:32 PDT | I14: Quinlan, Texas, United States
A15: Carolina Herrera | B15: Eau de Parfum | C15: 43.49 | D15: US $43.49/ea | E15: 2 | F15: 2 available / 20 sold | G15: 20 | H15: May 22, 2024 10:25:36 PDT | I15: Cincinnati, Ohio, United States
A16: Coach | B16: Eau de Parfum | C16: 29.2 | D16: US $29.20/ea | E16: 10 | F16: More than 10 available / 505 sold | G16: 505 | H16: May 08, 2024 09:46:06 PDT | I16: Edison, New Jersey, United States
A17: Guerlain | B17: Eau de Parfum | C17: 13 | D17: US $13.00 | E17: 10 | F17: More than 10 available / 94 sold | G17: 94 | H17: May 24, 2024 09:43:51 PDT | I17: New York, New York, United States
A18: Philosophy | B18: Eau De Parfum | C18: 39.69 | D18: US $39.69/ea | E18: 10 | F18: More than 10 available / 234 sold | G18: 234 | H18: May 24, 2024 10:21:14 PDT | I18: Edison, New Jersey, United States
A19: Marc Jacobs | B19: Eau de Parfum | C19: 59.99 | D19: US $59.99 | E19: 6 | F19: 6 available / 34 sold | G19: 34 | H19: May 22, 2024 18:32:01 PDT | I19: New York,USA, Hong Kong
A20: AS SHOWN | B20: Eau de Parfum | C20: 59.99 | D20: US $59.99 | F20: Last One / 43 sold | G20: 43 | H20: May 23, 2024 01:10:19 PDT | I20: New York, New York, United States
A21: Dolce & Gabbana | B21: Eau de Parfum | C21: 11 | D21: US $11.00 | E21: 10 | F21: More than 10 available / 1,613 sold | G21: 1613 | H21: Apr 05, 2024 00:52:19 PDT | I21: Albany, New York, United States
A22: QRC | B22: Spray | C22: 27 | D22: US $27.00/ea | E22: 10 | F22: More than 10 available / 218 sold | G22: 218 | H22: Mar 20, 2024 12:14:58 PDT | I22: Oklahoma City, Oklahoma, United States
A23: ~ CREPE ERASE ~ | B23: ~ BODY FIRM ADVANCED BODY REPAIR TREATMENT ~ | C23: 29.99 | D23: US $29.99 | E23: 10 | F23: More than 10 available / 1 sold | G23: 1 | I23: Melrose Park, Illinois, United States
A24: Unbranded | B24: Eau de Parfum | C24: 16.27 | D24: US $16.27/ea | E24: 300 | F24: 300 available / 38 sold | G24: 38 | H24: May 24, 2024 08:20:15 PDT | I24: shanghai, China
A25: YSL | B25: Eau de Parfum | C25: 54.95 | D25: US $54.95 | F25: Last One / 25 sold | G25: 25 | H25: May 24, 2024 00:08:02 PDT | I25: Stuyvesant Falls, New York, United States
A26: Carolina Herrera | B26: Eau de Parfum | C26: 49.99 | D26: US $49.99/ea | E26: 6 | F26: 6 available / 183 sold | G26: 183 | H26: May 23, 2024 09:40:39 PDT | I26: Macomb, Michigan, United States
A27: Parfums de Marly | B27: Eau de Parfum | C27: 84.99 | D27: US $84.99 | E27: 4 | F27: 4 available / 71 sold | G27: 71 | H27: May 22, 2024 01:30:45 PDT | I27: California or Hong Kong, Hong Kong
A28: Yves Saint Laurent | B28: Eau de Parfum | C28: 39.99 | D28: US $39.99/ea | E28: 8 | F28: 8 available / 126 sold | G28: 126 | H28: May 24, 2024 05:51:11 PDT | I28: Farmington, Michigan, United States
A29: Dolce&Gabbana | B29: Eau de Toilette | C29: 53.99 | D29: US $53.99 | F29: Out of Stock / 54 sold | G29: 54 | H29: May 24, 2024 03:14:29 PDT | I29: Ecorse, Michigan, United States
A30: EX NIHILO | B30: Eau de Parfum | C30: 99.99 | D30: US $99.99 | E30: 4 | F30: 4 available / 29 sold | G30: 29 | H30: May 23, 2024 03:50:04 PDT | I30: California or Hong Kong, Hong Kong
A31: Juliette has a gun | B31: Eau de Parfum | C31: 40.92 | D31: US $40.92/ea | F31: Limited quantity available / 1,571 sold | G31: 1571 | H31: May 24, 2024 07:32:36 PDT | I31: Hackensack, New Jersey, United States
A32: Davidoff | B32: Eau de Toilette | C32: 22.9 | D32: US $22.90/ea | E32: 10 | F32: More than 10 available / 291 sold | G32: 291 | H32: May 08, 2024 17:11:47 PDT | I32: Princeton Junction, New Jersey, United States
A33: Viktor & Rolf | B33: Eau de Parfum | C33: 42 | D33: US $42.00/ea | E33: 4 | F33: 4 available / 406 sold | G33: 406 | H33: May 23, 2024 22:57:33 PDT | I33: Portland, Oregon, United States
A34: Giorgi^o Armani | B34: Eau de Parfum | C34: 44.88 | D34: US $44.88/ea | E34: 7 | F34: 7 available / 147 sold | G34: 147 | H34: May 20, 2024 00:21:18 PDT | I34: South El Monte, California, United States
A35: PRADA | B35: Eau de Parfum | C35: 66.99 | D35: US $66.99 | E35: 10 | F35: More than 10 available / 3 sold | G35: 3 | H35: May 23, 2024 18:00:47 PDT | I35: Perth Amboy, New Jersey, United States
A36: Roja | B36: Eau de Parfum | C36: 129.99 | D36: US $129.99 | E36: 5 | F36: 5 available / 37 sold | G36: 37 | H36: May 24, 2024 09:25:04 PDT | I36: United States, Canada
A37: AS SHOWN | B37: Eau de Parfum | C37: 22.99 | D37: US $22.99 | E37: 10 | F37: 10 available / 11 sold | G37: 11 | H37: May 24, 2024 06:30:59 PDT | I37: CA, China
A38: Parfums de Marly | B38: Parfum | C38: 12 | D38: US $12.00 | E38: 10 | F38: More than 10 available / 59 sold | G38: 59 | I38: Albany, New York, United States
A39: Marc Jacobs | B39: Eau de Toilette | C39: 32.95 | D39: US $32.95 | E39: 10 | F39: More than 10 available / 68 sold | G39: 68 | H39: May 17, 2024 04:50:31 PDT | I39: College Point, New York, United States
A40: Ariana Grande | B40: Eau de Parfum | C40: 31.05 | D40: US $31.05/ea | E40: 9 | F40: 9 available / 54 sold | G40: 54 | H40: May 23, 2024 21:28:14 PDT | I40: Detroit, Michigan, United States
...
